Traceback (most recent call last):
  File "/home/seobyl/miniconda3/lib/python3.10/site-packages/wandb/sdk/wandb_config.py", line 162, in __getattr__
    return self.__getitem__(key)
  File "/home/seobyl/miniconda3/lib/python3.10/site-packages/wandb/sdk/wandb_config.py", line 130, in __getitem__
    return self._items[key]
KeyError: 'updata'
The above exception was the direct cause of the following exception:
Traceback (most recent call last):
  File "/nas/home/seobyl/CV_project/fortmux.py", line 43, in <module>
    wandb.config.updata(CFG)
  File "/home/seobyl/miniconda3/lib/python3.10/site-packages/wandb/sdk/wandb_config.py", line 164, in __getattr__
    raise AttributeError(
AttributeError: <class 'wandb.sdk.wandb_config.Config'> object has no attribute 'updata'